Workbook

Sheet 1_품목 등록자료 변경하기
A1: 품목코드 | B1: 품목명 | C1: 규격구분 | D1: 규격 | E1: 단위 EA,PACK,BOX,KG,포 | F1: 바코드 | G1: 바코드숫자 | H1: 박스바코드 | I1: 실제바코드
A2: 00000001 | B2: 배송료 | C2: 1 | H2: 99999999 | I2: =IFERROR(VLOOKUP(A2,Sheet1!$A$18:$E$2935,5,0),"")
A3: 00000006 | B3: GARUDA 땅콩과자 계란맛 | C3: 1 | D3: 230G X 1EA | E3: EA | F3: 8992775212103 | G3: 8992775212103 | H3: 8992775212103 | I3: =IFERROR(VLOOKUP(A3,Sheet1!$A$18:$E$2935,5,0),"")
A4: 00000009 | B4: GARUDA 까장쿨릿 | C4: 1 | D4: 180G X 1EA | E4: EA | F4: 8992775110126 | G4: 8992775110126 | H4: 8992775110140 | I4: =IFERROR(VLOOKUP(A4,Sheet1!$A$18:$E$2935,5,0),"")
A5: 00000010 | B5: TRUNG THANH 가지피클 | C5: 1 | D5: 500G X 12EA | E5: BOX | F5: 8934752030010 | G5: 8934752030010 | H5: 18924752030017 | I5: =IFERROR(VLOOKUP(A5,Sheet1!$A$18:$E$2935,5,0),"")
A6: 00000011 | B6: TRUNG THANH 가지피클 | C6: 1 | D6: 500G X 1EA | E6: EA | F6: 8934752030010 | G6: 8934752030010 | H6: 8934752030010 | I6: =IFERROR(VLOOKUP(A6,Sheet1!$A$18:$E$2935,5,0),"")
A7: 00000012 | B7: TRUNG THANH 양념가지피클 | C7: 1 | D7: 410G X 24EA | E7: BOX | F7: 8934752030133 | G7: 8934752030133 | H7: 18934752030130 | I7: =IFERROR(VLOOKUP(A7,Sheet1!$A$18:$E$2935,5,0),"")
A8: 00000013 | B8: TRUNG THANH 양념가지피클 | C8: 1 | D8: 410G X 1EA | E8: EA | F8: 8934752030133 | G8: 8934752030133 | H8: 8934752030133 | I8: =IFERROR(VLOOKUP(A8,Sheet1!$A$18:$E$2935,5,0),"")
A9: 00000014 | B9: 쏠티드 쉬림페이스트 200G(KAPI) | C9: 1 | D9: 200G X 36EA | E9: BOX | F9: 8853237000150 | G9: 8853237000150 | H9: 28853237000154 | I9: =IFERROR(VLOOKUP(A9,Sheet1!$A$18:$E$2935,5,0),"")
A10: 00000015 | B10: 쏠티드 쉬림페이스트 200G(KAPI) | C10: 1 | D10: 200G X 1EA | E10: EA | F10: 8853237000150 | G10: 8853237000150 | H10: 8853237000150 | I10: =IFERROR(VLOOKUP(A10,Sheet1!$A$18:$E$2935,5,0),"")
A11: 00000018 | B11: ROTARY 갈릭크래커 | C11: 1 | D11: 250G X 1EA | E11: EA | F11: 8993507000227 | G11: 8993507000227 | H11: 8993507000227 | I11: =IFERROR(VLOOKUP(A11,Sheet1!$A$18:$E$2935,5,0),"")
A12: 00000019 | B12: SEKAR BUMI 개구리다리(FROG LEG) | C12: 1 | D12: 400G X 1EA | E12: EA | F12: 8992704003635 | G12: 8992704003635 | H12: 8992704003635 | I12: =IFERROR(VLOOKUP(A12,Sheet1!$A$18:$E$2935,5,0),"")
A13: 00000022 | B13: TRUNG THANH 고추피클(PICKLED CHILI) | C13: 1 | D13: 320G X 24EA | E13: BOX | F13: 8934752030188 | G13: 8934752030188 | H13: 18934752030185 | I13: =IFERROR(VLOOKUP(A13,Sheet1!$A$18:$E$2935,5,0),"")
A14: 00000023 | B14: TRUNG THANH 고추피클(PICKLED CHILI) | C14: 1 | D14: 320G X 1EA | E14: EA | F14: 8934752030188 | G14: 8934752030188 | H14: 8934752030188 | I14: =IFERROR(VLOOKUP(A14,Sheet1!$A$18:$E$2935,5,0),"")
... A18: 00000033 | B18: CHEFS 그린잭플룻(KANOONTOM) | C18: 1 | D18: 565G X 1EA | E18: EA | F18: 093856991127 | G18: 0093856991127 | H18: 10093856991124 | I18: =IFERROR(VLOOKUP(A18,Sheet1!$A$18:$E$2935,5,0),"") -> 093856991127
A19: 00000034 | B19: NAMJAI 그린커리페이스트100G | C19: 1 | D19: 100G X 12EA | E19: PACK | F19: 8850173320144 | G19: 8850173320144 | I19: =IFERROR(VLOOKUP(A19,Sheet1!$A$18:$E$2935,5,0),"") -> 0
A20: 00000035 | B20: NO1 레몬그린티(LEMON GREEN TEA) | C20: 1 | D20: 455ML X 24EA | E20: BOX | F20: 8936193070280 | G20: 8936193070280 | H20: 18936006170302 | I20: =IFERROR(VLOOKUP(A20,Sheet1!$A$18:$E$2935,5,0),"") -> 0
A21: 00000036 | B21: NO1 레몬그린티(LEMON GREEN TEA) | C21: 1 | D21: 455ML X 1EA | E21: EA | F21: 8936193070280 | G21: 8936193070280 | H21: 8936193070280 | I21: =IFERROR(VLOOKUP(A21,Sheet1!$A$18:$E$2935,5,0),"") -> 0
A22: 00000048 | B22: ACECOOK 오라이시 후티우남방 | C22: 1 | D22: 70G X 24EA | E22: BOX | F22: 8934563453145 | G22: 8934563453145 | H22: 8934563070335 | I22: =IFERROR(VLOOKUP(A22,Sheet1!$A$18:$E$2935,5,0),"") -> 0
A23: 00000049 | B23: ACECOOK 오라이시 후티우남방 | C23: 1 | D23: 70G X 1EA | E23: EA | F23: 8934563453145 | G23: 8934563453145 | H23: 8934563453145 | I23: =IFERROR(VLOOKUP(A23,Sheet1!$A$18:$E$2935,5,0),"") -> 0
A24: 00000052 | B24: 메프라놈 남픽파우114G | C24: 1 | D24: 114G X 24EA | E24: BOX | F24: 8850487001111 | G24: 8850487001111 | H24: 18850487001118 | I24: =IFERROR(VLOOKUP(A24,Sheet1!$A$18:$E$2935,5,0),"") -> 0
A25: 00000053 | B25: 메프라놈 남픽파우114G | C25: 1 | D25: 114G X 1EA | E25: EA | F25: 8850487001111 | G25: 8850487001111 | H25: 8850487001111 | I25: =IFERROR(VLOOKUP(A25,Sheet1!$A$18:$E$2935,5,0),"") -> 0
A26: 00000054 | B26: 낭렛(튀긴 쌀과자)(NANGLED) | C26: 1 | D26: 220G X 1EA | E26: EA | F26: 8851710042611 | G26: 8851710042611 | H26: 8851710042611 | I26: =IFERROR(VLOOKUP(A26,Sheet1!$A$18:$E$2935,5,0),"") -> 0
A27: 00000062 | B27: FS 냉동바나나(F. BANANA) | C27: 1 | D27: 500G X 1EA | E27: EA | F27: 8936084330059 | G27: 8936084330059 | H27: 8936084330059 | I27: =IFERROR(VLOOKUP(A27,Sheet1!$A$18:$E$2935,5,0),"") -> 0
A28: 00000072 | B28: SAYAM 넴(NAEM) | C28: 1 | D28: 290g x 1EA | E28: EA | F28: 1248673593033 | G28: 1248673593033 | H28: 1248673593033 | I28: =IFERROR(VLOOKUP(A28,Sheet1!$A$18:$E$2935,5,0),"") -> 0
A29: 00000077 | B29: CHEFS 니파팜(ATTAP SEED) | C29: 1 | D29: 565G X 24EA | E29: BOX | F29: 0093856997709 | G29: 0093856997709 | H29: 10093856997706 | I29: =IFERROR(VLOOKUP(A29,Sheet1!$A$18:$E$2935,5,0),"") -> 0
A30: 00000078 | B30: CHEFS 니파팜(ATTAP SEED) | C30: 1 | D30: 565G X 1EA | E30: EA | F30: 093856997709 | G30: 0093856997709 | H30: 093856997709 | I30: =IFERROR(VLOOKUP(A30,Sheet1!$A$18:$E$2935,5,0),"") -> 093856997709
A31: 00000083 | B31: 닭간(닭부속물) | C31: 1 | D31: 400G X 1EA | E31: EA | F31: 8809120644574 | G31: 8809120644574 | H31: 8809120644574 | I31: =IFERROR(VLOOKUP(A31,Sheet1!$A$18:$E$2935,5,0),"") -> 0
... A69: 00000132 | B69: DAAL 레드루비아 | C69: 1 | D69: 800G X 1EA | E69: EA | F69: 7700000000029 | G69: 7700000000029 | H69: 7700000000029 | I69: =IFERROR(VLOOKUP(A69,Sheet1!$A$18:$E$2935,5,0),"") -> 0
A70: 00000133 | B70: NAMJAI 레드커리페이스트 100G | C70: 1 | D70: 100G X 12EA | E70: PACK | F70: 8850173310145 | G70: 8850173310145 | I70: =IFERROR(VLOOKUP(A70,Sheet1!$A$18:$E$2935,5,0),"") -> 0
A71: 00000135 | B71: 이태리 레몬쥬스 | C71: 1 | D71: 200ML X 1EA | E71: EA | F71: 8009490000684 | G71: 8009490000684 | H71: 8009490000684 | I71: =IFERROR(VLOOKUP(A71,Sheet1!$A$18:$E$2935,5,0),"") -> 0
A72: 00000136 | B72: 렌긴안아신 | C72: 1 | D72: 330G X 1EA | E72: EA | F72: 8993334101241 | G72: 8993334101241 | H72: 8993334101241 | I72: =IFERROR(VLOOKUP(A72,Sheet1!$A$18:$E$2935,5,0),"") -> 0
A73: 00000137 | B73: 렌틸콩(LENS CULINARIS) | C73: 1 | D73: 500G X 20EA | E73: BOX | F73: 9876543212224 | G73: 9876543212224 | H73: 7700000000031 | I73: =IFERROR(VLOOKUP(A73,Sheet1!$A$18:$E$2935,5,0),"") -> 0
A74: 00000139 | B74: AJINOMOTO 푸드시즈닝치킨플레이버 75G | C74: 1 | D74: 75G X 120EA | E74: BOX | F74: 8850250010975 | G74: 8850250010975 | H74: 48850250001711 | I74: =IFERROR(VLOOKUP(A74,Sheet1!$A$18:$E$2935,5,0),"") -> 0
A75: 00000140 | B75: AJINOMOTO 푸드시즈닝치킨플레이버 75G | C75: 1 | D75: 75G X 10EA | E75: PACK | F75: 8850250010975 | G75: 8850250010975 | H75: 8850250011712 | I75: =IFERROR(VLOOKUP(A75,Sheet1!$A$18:$E$2935,5,0),"") -> 0
A76: 00000141 | B76: AJINOMOTO 푸드시즈닝치킨플레이버 75G | C76: 1 | D76: 75G X 1EA | E76: EA | F76: 8850250010975 | G76: 8850250010975 | H76: 8850250010975 | I76: =IFERROR(VLOOKUP(A76,Sheet1!$A$18:$E$2935,5,0),"") -> 0
A77: 00000142 | B77: AJINOMOTO 푸드시즈닝포크플레이버(로띠무) 400G(대) | C77: 1 | D77: 400G X 20EA | E77: BOX | F77: 8850250010951 | G77: 8850250010951 | H77: 88502500110404 | I77: =IFERROR(VLOOKUP(A77,Sheet1!$A$18:$E$2935,5,0),"") -> 0
A78: 00000143 | B78: AJINOMOTO 푸드시즈닝포크플레이버(로띠무) 400G(대) | C78: 1 | D78: 400G X 5EA | E78: PACK | F78: 8850250010951 | G78: 8850250010951 | H78: 8850250011040 | I78: =IFERROR(VLOOKUP(A78,Sheet1!$A$18:$E$2935,5,0),"") -> 0
A79: 00000144 | B79: AJINOMOTO 푸드시즈닝포크플레이버 400G | C79: 1 | D79: 400G X 1EA | E79: EA | F79: 8850250010951 | G79: 8850250010951 | H79: 8850250010951 | I79: =IFERROR(VLOOKUP(A79,Sheet1!$A$18:$E$2935,5,0),"") -> 0
A80: 00000145 | B80: AJINOMOTO 푸드시즈닝포크플레이버 75G | C80: 1 | D80: 75G X 160EA | E80: BOX | F80: 8850250010937 | G80: 8850250010937 | H80: 58850250001725 | I80: =IFERROR(VLOOKUP(A80,Sheet1!$A$18:$E$2935,5,0),"") -> 0
...

Sheet Sheet1
A1: 품목코드 | B1: 품목명 | C1: 단위 | D1: 바코드 | E1: 실제바코드 | F1: 등록바코드 | G1: 규격
A2: 00000001 | B2: 배송료
A3: 00000006 | B3: GARUDA 땅콩과자 계란맛 | C3: EA | D3: 8992775212103 | F3: 8992775212103 | G3: 230G X 1EA
A4: 00000009 | B4: GARUDA 까장쿨릿 | C4: EA | D4: 8992775110126 | F4: 8992775110126 | G4: 180G X 1EA
A5: 00000010 | B5: TRUNG THANH 가지피클 | C5: BOX | D5: 8934752030010 | F5: 8934752030010 | G5: 500G X 12EA
A6: 00000011 | B6: TRUNG THANH 가지피클 | C6: EA | D6: 8934752030010 | F6: 8934752030010 | G6: 500G X 1EA
A7: 00000012 | B7: TRUNG THANH 양념가지피클 | C7: BOX | D7: 8934752030133 | F7: 8934752030133 | G7: 410G X 24EA
A8: 00000013 | B8: TRUNG THANH 양념가지피클 | C8: EA | D8: 8934752030133 | F8: 8934752030133 | G8: 410G X 1EA
A9: 00000014 | B9: 쏠티드 쉬림페이스트 200G(KAPI) | C9: BOX | D9: 8853237000150 | F9: 8853237000150 | G9: 200G X 36EA
A10: 00000015 | B10: 쏠티드 쉬림페이스트 200G(KAPI) | C10: EA | D10: 8853237000150 | F10: 8853237000150 | G10: 200G X 1EA
A11: 00000018 | B11: ROTARY 갈릭크래커 | C11: EA | D11: 8993507000227 | F11: 8993507000227 | G11: 250G X 1EA
A12: 00000019 | B12: SEKAR BUMI 개구리다리(FROG LEG) | C12: EA | D12: 8992704003635 | F12: 8992704003635 | G12: 400G X 1EA
A13: 00000022 | B13: TRUNG THANH 고추피클(PICKLED CHILI) | C13: BOX | D13: 8934752030188 | F13: 8934752030188 | G13: 320G X 24EA
A14: 00000023 | B14: TRUNG THANH 고추피클(PICKLED CHILI) | C14: EA | D14: 8934752030188 | F14: 8934752030188 | G14: 320G X 1EA
... A17: 00000026 | B17: YWY 굴소스850G | C17: EA | D17: 8850206252848 | F17: 8850206252848 | G17: 850G X 1EA
A18: 00000033 | B18: CHEFS 그린잭플룻(KANOONTOM) | C18: EA | D18: 0093856991127 | E18: 093856991127 | F18: 0093856991127 | G18: 565G X 1EA
A19: 00000034 | B19: NAMJAI 그린커리페이스트100G | C19: PACK | D19: 8850173320144 | F19: 8850173320144 | G19: 100G X 12EA
A20: 00000035 | B20: NO1 레몬그린티(LEMON GREEN TEA) | C20: BOX | D20: 8936193070280 | F20: 8936193070280 | G20: 455ML X 24EA
A21: 00000036 | B21: NO1 레몬그린티(LEMON GREEN TEA) | C21: EA | D21: 8936193070280 | F21: 8936193070280 | G21: 455ML X 1EA
A22: 00000048 | B22: ACECOOK 오라이시 후티우남방 | C22: BOX | D22: 8934563453145 | F22: 8934563453145 | G22: 70G X 24EA
A23: 00000049 | B23: ACECOOK 오라이시 후티우남방 | C23: EA | D23: 8934563453145 | F23: 8934563453145 | G23: 70G X 1EA
A24: 00000052 | B24: 메프라놈 남픽파우114G | C24: BOX | D24: 8850487001111 | F24: 8850487001111 | G24: 114G X 24EA
A25: 00000053 | B25: 메프라놈 남픽파우114G | C25: EA | D25: 8850487001111 | F25: 8850487001111 | G25: 114G X 1EA
A26: 00000054 | B26: 낭렛(튀긴 쌀과자)(NANGLED) | C26: EA | D26: 8851710042611 | F26: 8851710042611 | G26: 220G X 1EA
A27: 00000062 | B27: FS 냉동바나나(F. BANANA) | C27: EA | D27: 8936084330059 | F27: 8936084330059 | G27: 500G X 1EA
A28: 00000072 | B28: SAYAM 넴(NAEM) | C28: EA | D28: 1248673593033 | F28: 1248673593033 | G28: 290g x 1EA
A29: 00000077 | B29: CHEFS 니파팜(ATTAP SEED) | C29: BOX | D29: 0093856997709 | F29: 0093856997709 | G29: 565G X 24EA
A30: 00000078 | B30: CHEFS 니파팜(ATTAP SEED) | C30: EA | D30: 0093856997709 | E30: 093856997709 | F30: 0093856997709 | G30: 565G X 1EA
A31: 00000083 | B31: 닭간(닭부속물) | C31: EA | D31: 8809120644574 | F31: 8809120644574 | G31: 400G X 1EA
A32: 00000087 | B32: 닭알집(닭부속물) | C32: EA | D32: 8809120644604 | F32: 8809120644604 | G32: 550G X 1EA
A33: 00000088 | B33: 닭염통(닭부속물) | C33: EA | D33: 8809120644611 | F33: 8809120644611 | G33: 350G X 1EA
A34: 00000089 | B34: 대추야자(KHALAS-1KG) | C34: BOX | D34: 6297000361819 | F34: 6297000361819 | G34: 1KG X 10EA
A35: 00000090 | B35: 대추야자(KHALAS-1KG) | C35: EA | D35: 6297000361819 | F35: 6297000361819 | G35: 1KG X 1EA
A36: 00000092 | B36: 데시케이트-베트남(V KAKMAPAW) | C36: BOX | D36: 8936062100605 | F36: 8936062100605 | G36: 250G X 24EA
A37: 00000093 | B37: 데시케이트-베트남(V KAKMAPAW) | C37: EA | D37: 8936062100605 | F37: 8936062100605 | G37: 250G X 1EA
A38: 00000094 | B38: 데시케이트-인도네시아(IN KAKMAPAW) | C38: EA | D38: 8997220050071 | F38: 8997220050071 | G38: 200G X 1EA
A39: 00000095 | B39: 생두리안(DURIAN) | C39: BOX | D39: 7700000000026 | F39: 7700000000026 | G39: 10KG
A40: 00000096 | B40: HATARI 두리안비스킷(DURIAN BISCUITS) | C40: EA | D40: 8997025914301 | F40: 8997025914301 | G40: 210G X 1PACK
A41: 00000098 | B41: 두부(차오)(CHAO) | C41: EA | D41: 7700000000027 | F41: 7700000000027 | G41: 400G X 1EA
A42: 00000100 | B42: TANTAN 땅콩(탄탄) | C42: BOX | D42: 8809548611400 | F42: 8809548611400 | G42: 800G X 12EA
...
